<robot xmlns:xacro="http://www.ros.org/wiki/xacro">

  <!-- Steering Link + Joint -->
  <xacro:macro name="steering" params="locationprefix locx locy orix oriy">
    <link name="${locationprefix}_steering_link">
      <inertial>
        <origin xyz="${orix} ${oriy} -0.062952735634349" rpy="0 0 0" />
        <mass value="0.457040227435217" />
        <inertia ixx="0.000506316019133546" ixy="2.57036028131297E-12" ixz="-2.94559820026048E-07" iyy="0.000647499727635714" iyz="1.16491986588291E-08" izz="0.00027829904639192" />
      </inertial>
      <visual>
        <origin xyz="0 0 0" rpy="0 0 0" />
        <geometry>
          <mesh filename="file://$(find swerve_robot_description)/meshes/${locationprefix}_steering_link.dae" />
        </geometry>
      </visual>
      <collision>
        <origin xyz="0 0 0" rpy="0 0 0" />
        <geometry>
          <mesh filename="file://$(find swerve_robot_description)/meshes/${locationprefix}_steering_link.dae" />
        </geometry>
      </collision>
    </link>

    <gazebo reference="${locationprefix}_steering_link">
      <material>Gazebo/Grey</material>
    </gazebo>

    <joint name="steering_${locationprefix}_joint" type="revolute">
      <origin xyz="${locx} ${locy} -0.077" rpy="0 0 0" />
      <parent link="chassis_link" />
      <child link="${locationprefix}_steering_link" />
      <axis xyz="0 0 1" />
      <limit effort="20" velocity="6.28" lower="-1.57" upper="1.57" />
    </joint>

  </xacro:macro>

</robot>
